{
 "cells": [
  {
   "cell_type": "code",
   "execution_count": 1,
   "metadata": {
    "collapsed": true
   },
   "outputs": [],
   "source": [
    "import tensorflow as tf"
   ]
  },
  {
   "cell_type": "code",
   "execution_count": 2,
   "metadata": {
    "collapsed": true
   },
   "outputs": [],
   "source": [
    "from tensorflow import keras"
   ]
  },
  {
   "cell_type": "code",
   "execution_count": 4,
   "metadata": {
    "collapsed": true
   },
   "outputs": [],
   "source": [
    "from tensorflow.keras.preprocessing.image import ImageDataGenerator"
   ]
  },
  {
   "cell_type": "code",
   "execution_count": 3,
   "metadata": {},
   "outputs": [
    {
     "name": "stdout",
     "output_type": "stream",
     "text": [
      "ERROR! Session/line number was not unique in database. History logging moved to new session 25\n"
     ]
    }
   ],
   "source": [
    "import matplotlib.pyplot as plt"
   ]
  },
  {
   "cell_type": "code",
   "execution_count": 5,
   "metadata": {
    "collapsed": true
   },
   "outputs": [],
   "source": [
    "import matplotlib.pyplot as plt"
   ]
  },
  {
   "cell_type": "code",
   "execution_count": 6,
   "metadata": {
    "collapsed": true
   },
   "outputs": [],
   "source": [
    "img_gen=ImageDataGenerator( rotation_range=45, width_shift_range=0.20,height_shift_range=0.20,shear_range=0.20,\n",
    "                           zoom_range=0.20, horizontal_flip=True,vertical_flip=True,fill_mode='nearest')"
   ]
  },
  {
   "cell_type": "code",
   "execution_count": 7,
   "metadata": {},
   "outputs": [
    {
     "data": {
      "text/plain": [
       "<tensorflow.python.keras.preprocessing.image.ImageDataGenerator at 0x1c3ca2dcba8>"
      ]
     },
     "execution_count": 7,
     "metadata": {},
     "output_type": "execute_result"
    }
   ],
   "source": [
    "img_gen"
   ]
  },
  {
   "cell_type": "code",
   "execution_count": null,
   "metadata": {},
   "outputs": [
    {
     "name": "stderr",
     "output_type": "stream",
     "text": [
      "ERROR:root:Internal Python error in the inspect module.\n",
      "Below is the traceback from this internal error.\n",
      "\n",
      "ERROR:root:Internal Python error in the inspect module.\n",
      "Below is the traceback from this internal error.\n",
      "\n",
      "ERROR:root:Internal Python error in the inspect module.\n",
      "Below is the traceback from this internal error.\n",
      "\n"
     ]
    },
    {
     "name": "stdout",
     "output_type": "stream",
     "text": [
      "Traceback (most recent call last):\n",
      "  File \"C:\\Users\\SANDEEP\\anaconda3\\envs\\tesnorflow\\lib\\site-packages\\IPython\\core\\interactiveshell.py\", line 3343, in run_code\n",
      "    exec(code_obj, self.user_global_ns, self.user_ns)\n",
      "  File \"<ipython-input-8-11ce660de77b>\", line 1, in <module>\n",
      "    from skimage import io\n",
      "ModuleNotFoundError: No module named 'skimage'\n",
      "\n",
      "During handling of the above exception, another exception occurred:\n",
      "\n",
      "Traceback (most recent call last):\n",
      "  File \"C:\\Users\\SANDEEP\\anaconda3\\envs\\tesnorflow\\lib\\site-packages\\IPython\\core\\interactiveshell.py\", line 2044, in showtraceback\n",
      "    stb = value._render_traceback_()\n",
      "AttributeError: 'ModuleNotFoundError' object has no attribute '_render_traceback_'\n",
      "\n",
      "During handling of the above exception, another exception occurred:\n",
      "\n",
      "Traceback (most recent call last):\n",
      "  File \"C:\\Users\\SANDEEP\\anaconda3\\envs\\tesnorflow\\lib\\site-packages\\IPython\\core\\ultratb.py\", line 1169, in get_records\n",
      "    return _fixed_getinnerframes(etb, number_of_lines_of_context, tb_offset)\n",
      "  File \"C:\\Users\\SANDEEP\\anaconda3\\envs\\tesnorflow\\lib\\site-packages\\IPython\\core\\ultratb.py\", line 316, in wrapped\n",
      "    return f(*args, **kwargs)\n",
      "  File \"C:\\Users\\SANDEEP\\anaconda3\\envs\\tesnorflow\\lib\\site-packages\\IPython\\core\\ultratb.py\", line 350, in _fixed_getinnerframes\n",
      "    records = fix_frame_records_filenames(inspect.getinnerframes(etb, context))\n",
      "  File \"C:\\Users\\SANDEEP\\anaconda3\\envs\\tesnorflow\\lib\\inspect.py\", line 1490, in getinnerframes\n",
      "    frameinfo = (tb.tb_frame,) + getframeinfo(tb, context)\n",
      "  File \"C:\\Users\\SANDEEP\\anaconda3\\envs\\tesnorflow\\lib\\inspect.py\", line 1448, in getframeinfo\n",
      "    filename = getsourcefile(frame) or getfile(frame)\n",
      "  File \"C:\\Users\\SANDEEP\\anaconda3\\envs\\tesnorflow\\lib\\inspect.py\", line 696, in getsourcefile\n",
      "    if getattr(getmodule(object, filename), '__loader__', None) is not None:\n",
      "  File \"C:\\Users\\SANDEEP\\anaconda3\\envs\\tesnorflow\\lib\\inspect.py\", line 733, in getmodule\n",
      "    if ismodule(module) and hasattr(module, '__file__'):\n",
      "  File \"C:\\Users\\SANDEEP\\anaconda3\\envs\\tesnorflow\\lib\\site-packages\\tensorflow\\__init__.py\", line 50, in __getattr__\n",
      "    module = self._load()\n",
      "  File \"C:\\Users\\SANDEEP\\anaconda3\\envs\\tesnorflow\\lib\\site-packages\\tensorflow\\__init__.py\", line 44, in _load\n",
      "    module = _importlib.import_module(self.__name__)\n",
      "  File \"C:\\Users\\SANDEEP\\anaconda3\\envs\\tesnorflow\\lib\\importlib\\__init__.py\", line 126, in import_module\n",
      "    return _bootstrap._gcd_import(name[level:], package, level)\n",
      "  File \"<frozen importlib._bootstrap>\", line 994, in _gcd_import\n",
      "  File \"<frozen importlib._bootstrap>\", line 971, in _find_and_load\n",
      "  File \"<frozen importlib._bootstrap>\", line 953, in _find_and_load_unlocked\n",
      "ModuleNotFoundError: No module named 'tensorflow_core.estimator'\n",
      "Traceback (most recent call last):\n",
      "  File \"C:\\Users\\SANDEEP\\anaconda3\\envs\\tesnorflow\\lib\\site-packages\\IPython\\core\\interactiveshell.py\", line 3343, in run_code\n",
      "    exec(code_obj, self.user_global_ns, self.user_ns)\n",
      "  File \"<ipython-input-8-11ce660de77b>\", line 1, in <module>\n",
      "    from skimage import io\n",
      "ModuleNotFoundError: No module named 'skimage'\n",
      "\n",
      "During handling of the above exception, another exception occurred:\n",
      "\n",
      "Traceback (most recent call last):\n",
      "  File \"C:\\Users\\SANDEEP\\anaconda3\\envs\\tesnorflow\\lib\\site-packages\\IPython\\core\\interactiveshell.py\", line 2044, in showtraceback\n",
      "    stb = value._render_traceback_()\n",
      "AttributeError: 'ModuleNotFoundError' object has no attribute '_render_traceback_'\n",
      "\n",
      "During handling of the above exception, another exception occurred:\n",
      "\n",
      "Traceback (most recent call last):\n",
      "  File \"C:\\Users\\SANDEEP\\anaconda3\\envs\\tesnorflow\\lib\\site-packages\\IPython\\core\\interactiveshell.py\", line 3263, in run_ast_nodes\n",
      "    if (await self.run_code(code, result,  async_=asy)):\n",
      "  File \"C:\\Users\\SANDEEP\\anaconda3\\envs\\tesnorflow\\lib\\site-packages\\IPython\\core\\interactiveshell.py\", line 3360, in run_code\n",
      "    self.showtraceback(running_compiled_code=True)\n",
      "  File \"C:\\Users\\SANDEEP\\anaconda3\\envs\\tesnorflow\\lib\\site-packages\\IPython\\core\\interactiveshell.py\", line 2047, in showtraceback\n",
      "    value, tb, tb_offset=tb_offset)\n",
      "  File \"C:\\Users\\SANDEEP\\anaconda3\\envs\\tesnorflow\\lib\\site-packages\\IPython\\core\\ultratb.py\", line 1436, in structured_traceback\n",
      "    self, etype, value, tb, tb_offset, number_of_lines_of_context)\n",
      "  File \"C:\\Users\\SANDEEP\\anaconda3\\envs\\tesnorflow\\lib\\site-packages\\IPython\\core\\ultratb.py\", line 1336, in structured_traceback\n",
      "    self, etype, value, tb, tb_offset, number_of_lines_of_context\n",
      "  File \"C:\\Users\\SANDEEP\\anaconda3\\envs\\tesnorflow\\lib\\site-packages\\IPython\\core\\ultratb.py\", line 1193, in structured_traceback\n",
      "    tb_offset)\n",
      "  File \"C:\\Users\\SANDEEP\\anaconda3\\envs\\tesnorflow\\lib\\site-packages\\IPython\\core\\ultratb.py\", line 1150, in format_exception_as_a_whole\n",
      "    last_unique, recursion_repeat = find_recursion(orig_etype, evalue, records)\n",
      "  File \"C:\\Users\\SANDEEP\\anaconda3\\envs\\tesnorflow\\lib\\site-packages\\IPython\\core\\ultratb.py\", line 451, in find_recursion\n",
      "    return len(records), 0\n",
      "TypeError: object of type 'NoneType' has no len()\n",
      "\n",
      "During handling of the above exception, another exception occurred:\n",
      "\n",
      "Traceback (most recent call last):\n",
      "  File \"C:\\Users\\SANDEEP\\anaconda3\\envs\\tesnorflow\\lib\\site-packages\\IPython\\core\\interactiveshell.py\", line 2044, in showtraceback\n",
      "    stb = value._render_traceback_()\n",
      "AttributeError: 'TypeError' object has no attribute '_render_traceback_'\n",
      "\n",
      "During handling of the above exception, another exception occurred:\n",
      "\n",
      "Traceback (most recent call last):\n",
      "  File \"C:\\Users\\SANDEEP\\anaconda3\\envs\\tesnorflow\\lib\\site-packages\\IPython\\core\\ultratb.py\", line 1169, in get_records\n",
      "    return _fixed_getinnerframes(etb, number_of_lines_of_context, tb_offset)\n",
      "  File \"C:\\Users\\SANDEEP\\anaconda3\\envs\\tesnorflow\\lib\\site-packages\\IPython\\core\\ultratb.py\", line 316, in wrapped\n",
      "    return f(*args, **kwargs)\n",
      "  File \"C:\\Users\\SANDEEP\\anaconda3\\envs\\tesnorflow\\lib\\site-packages\\IPython\\core\\ultratb.py\", line 350, in _fixed_getinnerframes\n",
      "    records = fix_frame_records_filenames(inspect.getinnerframes(etb, context))\n",
      "  File \"C:\\Users\\SANDEEP\\anaconda3\\envs\\tesnorflow\\lib\\inspect.py\", line 1490, in getinnerframes\n",
      "    frameinfo = (tb.tb_frame,) + getframeinfo(tb, context)\n",
      "  File \"C:\\Users\\SANDEEP\\anaconda3\\envs\\tesnorflow\\lib\\inspect.py\", line 1448, in getframeinfo\n",
      "    filename = getsourcefile(frame) or getfile(frame)\n",
      "  File \"C:\\Users\\SANDEEP\\anaconda3\\envs\\tesnorflow\\lib\\inspect.py\", line 696, in getsourcefile\n",
      "    if getattr(getmodule(object, filename), '__loader__', None) is not None:\n",
      "  File \"C:\\Users\\SANDEEP\\anaconda3\\envs\\tesnorflow\\lib\\inspect.py\", line 733, in getmodule\n",
      "    if ismodule(module) and hasattr(module, '__file__'):\n",
      "  File \"C:\\Users\\SANDEEP\\anaconda3\\envs\\tesnorflow\\lib\\site-packages\\tensorflow\\__init__.py\", line 50, in __getattr__\n",
      "    module = self._load()\n",
      "  File \"C:\\Users\\SANDEEP\\anaconda3\\envs\\tesnorflow\\lib\\site-packages\\tensorflow\\__init__.py\", line 44, in _load\n",
      "    module = _importlib.import_module(self.__name__)\n",
      "  File \"C:\\Users\\SANDEEP\\anaconda3\\envs\\tesnorflow\\lib\\importlib\\__init__.py\", line 126, in import_module\n",
      "    return _bootstrap._gcd_import(name[level:], package, level)\n",
      "  File \"<frozen importlib._bootstrap>\", line 994, in _gcd_import\n",
      "  File \"<frozen importlib._bootstrap>\", line 971, in _find_and_load\n",
      "  File \"<frozen importlib._bootstrap>\", line 953, in _find_and_load_unlocked\n",
      "ModuleNotFoundError: No module named 'tensorflow_core.estimator'\n",
      "Traceback (most recent call last):\n",
      "  File \"C:\\Users\\SANDEEP\\anaconda3\\envs\\tesnorflow\\lib\\site-packages\\IPython\\core\\interactiveshell.py\", line 3343, in run_code\n",
      "    exec(code_obj, self.user_global_ns, self.user_ns)\n",
      "  File \"<ipython-input-8-11ce660de77b>\", line 1, in <module>\n",
      "    from skimage import io\n",
      "ModuleNotFoundError: No module named 'skimage'\n",
      "\n",
      "During handling of the above exception, another exception occurred:\n",
      "\n",
      "Traceback (most recent call last):\n",
      "  File \"C:\\Users\\SANDEEP\\anaconda3\\envs\\tesnorflow\\lib\\site-packages\\IPython\\core\\interactiveshell.py\", line 2044, in showtraceback\n",
      "    stb = value._render_traceback_()\n",
      "AttributeError: 'ModuleNotFoundError' object has no attribute '_render_traceback_'\n",
      "\n",
      "During handling of the above exception, another exception occurred:\n",
      "\n",
      "Traceback (most recent call last):\n",
      "  File \"C:\\Users\\SANDEEP\\anaconda3\\envs\\tesnorflow\\lib\\site-packages\\IPython\\core\\interactiveshell.py\", line 3263, in run_ast_nodes\n",
      "    if (await self.run_code(code, result,  async_=asy)):\n",
      "  File \"C:\\Users\\SANDEEP\\anaconda3\\envs\\tesnorflow\\lib\\site-packages\\IPython\\core\\interactiveshell.py\", line 3360, in run_code\n",
      "    self.showtraceback(running_compiled_code=True)\n",
      "  File \"C:\\Users\\SANDEEP\\anaconda3\\envs\\tesnorflow\\lib\\site-packages\\IPython\\core\\interactiveshell.py\", line 2047, in showtraceback\n",
      "    value, tb, tb_offset=tb_offset)\n",
      "  File \"C:\\Users\\SANDEEP\\anaconda3\\envs\\tesnorflow\\lib\\site-packages\\IPython\\core\\ultratb.py\", line 1436, in structured_traceback\n",
      "    self, etype, value, tb, tb_offset, number_of_lines_of_context)\n",
      "  File \"C:\\Users\\SANDEEP\\anaconda3\\envs\\tesnorflow\\lib\\site-packages\\IPython\\core\\ultratb.py\", line 1336, in structured_traceback\n",
      "    self, etype, value, tb, tb_offset, number_of_lines_of_context\n",
      "  File \"C:\\Users\\SANDEEP\\anaconda3\\envs\\tesnorflow\\lib\\site-packages\\IPython\\core\\ultratb.py\", line 1193, in structured_traceback\n",
      "    tb_offset)\n",
      "  File \"C:\\Users\\SANDEEP\\anaconda3\\envs\\tesnorflow\\lib\\site-packages\\IPython\\core\\ultratb.py\", line 1150, in format_exception_as_a_whole\n",
      "    last_unique, recursion_repeat = find_recursion(orig_etype, evalue, records)\n",
      "  File \"C:\\Users\\SANDEEP\\anaconda3\\envs\\tesnorflow\\lib\\site-packages\\IPython\\core\\ultratb.py\", line 451, in find_recursion\n",
      "    return len(records), 0\n",
      "TypeError: object of type 'NoneType' has no len()\n",
      "\n",
      "During handling of the above exception, another exception occurred:\n",
      "\n",
      "Traceback (most recent call last):\n",
      "  File \"C:\\Users\\SANDEEP\\anaconda3\\envs\\tesnorflow\\lib\\site-packages\\IPython\\core\\interactiveshell.py\", line 2044, in showtraceback\n",
      "    stb = value._render_traceback_()\n",
      "AttributeError: 'TypeError' object has no attribute '_render_traceback_'\n",
      "\n",
      "During handling of the above exception, another exception occurred:\n",
      "\n",
      "Traceback (most recent call last):\n",
      "  File \"C:\\Users\\SANDEEP\\anaconda3\\envs\\tesnorflow\\lib\\site-packages\\IPython\\core\\interactiveshell.py\", line 2895, in _run_cell\n",
      "    return runner(coro)\n",
      "  File \"C:\\Users\\SANDEEP\\anaconda3\\envs\\tesnorflow\\lib\\site-packages\\IPython\\core\\async_helpers.py\", line 68, in _pseudo_sync_runner\n",
      "    coro.send(None)\n",
      "  File \"C:\\Users\\SANDEEP\\anaconda3\\envs\\tesnorflow\\lib\\site-packages\\IPython\\core\\interactiveshell.py\", line 3072, in run_cell_async\n",
      "    interactivity=interactivity, compiler=compiler, result=result)\n",
      "  File \"C:\\Users\\SANDEEP\\anaconda3\\envs\\tesnorflow\\lib\\site-packages\\IPython\\core\\interactiveshell.py\", line 3282, in run_ast_nodes\n",
      "    self.showtraceback()\n",
      "  File \"C:\\Users\\SANDEEP\\anaconda3\\envs\\tesnorflow\\lib\\site-packages\\IPython\\core\\interactiveshell.py\", line 2047, in showtraceback\n",
      "    value, tb, tb_offset=tb_offset)\n",
      "  File \"C:\\Users\\SANDEEP\\anaconda3\\envs\\tesnorflow\\lib\\site-packages\\IPython\\core\\ultratb.py\", line 1436, in structured_traceback\n",
      "    self, etype, value, tb, tb_offset, number_of_lines_of_context)\n",
      "  File \"C:\\Users\\SANDEEP\\anaconda3\\envs\\tesnorflow\\lib\\site-packages\\IPython\\core\\ultratb.py\", line 1336, in structured_traceback\n",
      "    self, etype, value, tb, tb_offset, number_of_lines_of_context\n",
      "  File \"C:\\Users\\SANDEEP\\anaconda3\\envs\\tesnorflow\\lib\\site-packages\\IPython\\core\\ultratb.py\", line 1211, in structured_traceback\n",
      "    chained_exceptions_tb_offset)\n",
      "  File \"C:\\Users\\SANDEEP\\anaconda3\\envs\\tesnorflow\\lib\\site-packages\\IPython\\core\\ultratb.py\", line 1150, in format_exception_as_a_whole\n",
      "    last_unique, recursion_repeat = find_recursion(orig_etype, evalue, records)\n",
      "  File \"C:\\Users\\SANDEEP\\anaconda3\\envs\\tesnorflow\\lib\\site-packages\\IPython\\core\\ultratb.py\", line 451, in find_recursion\n",
      "    return len(records), 0\n",
      "TypeError: object of type 'NoneType' has no len()\n",
      "\n",
      "During handling of the above exception, another exception occurred:\n",
      "\n",
      "Traceback (most recent call last):\n",
      "  File \"C:\\Users\\SANDEEP\\anaconda3\\envs\\tesnorflow\\lib\\site-packages\\IPython\\core\\interactiveshell.py\", line 2044, in showtraceback\n",
      "    stb = value._render_traceback_()\n",
      "AttributeError: 'TypeError' object has no attribute '_render_traceback_'\n",
      "\n",
      "During handling of the above exception, another exception occurred:\n",
      "\n",
      "Traceback (most recent call last):\n",
      "  File \"C:\\Users\\SANDEEP\\anaconda3\\envs\\tesnorflow\\lib\\site-packages\\IPython\\core\\ultratb.py\", line 1169, in get_records\n",
      "    return _fixed_getinnerframes(etb, number_of_lines_of_context, tb_offset)\n",
      "  File \"C:\\Users\\SANDEEP\\anaconda3\\envs\\tesnorflow\\lib\\site-packages\\IPython\\core\\ultratb.py\", line 316, in wrapped\n",
      "    return f(*args, **kwargs)\n",
      "  File \"C:\\Users\\SANDEEP\\anaconda3\\envs\\tesnorflow\\lib\\site-packages\\IPython\\core\\ultratb.py\", line 350, in _fixed_getinnerframes\n",
      "    records = fix_frame_records_filenames(inspect.getinnerframes(etb, context))\n",
      "  File \"C:\\Users\\SANDEEP\\anaconda3\\envs\\tesnorflow\\lib\\inspect.py\", line 1490, in getinnerframes\n",
      "    frameinfo = (tb.tb_frame,) + getframeinfo(tb, context)\n",
      "  File \"C:\\Users\\SANDEEP\\anaconda3\\envs\\tesnorflow\\lib\\inspect.py\", line 1448, in getframeinfo\n",
      "    filename = getsourcefile(frame) or getfile(frame)\n",
      "  File \"C:\\Users\\SANDEEP\\anaconda3\\envs\\tesnorflow\\lib\\inspect.py\", line 696, in getsourcefile\n",
      "    if getattr(getmodule(object, filename), '__loader__', None) is not None:\n",
      "  File \"C:\\Users\\SANDEEP\\anaconda3\\envs\\tesnorflow\\lib\\inspect.py\", line 733, in getmodule\n",
      "    if ismodule(module) and hasattr(module, '__file__'):\n",
      "  File \"C:\\Users\\SANDEEP\\anaconda3\\envs\\tesnorflow\\lib\\site-packages\\tensorflow\\__init__.py\", line 50, in __getattr__\n",
      "    module = self._load()\n",
      "  File \"C:\\Users\\SANDEEP\\anaconda3\\envs\\tesnorflow\\lib\\site-packages\\tensorflow\\__init__.py\", line 44, in _load\n",
      "    module = _importlib.import_module(self.__name__)\n",
      "  File \"C:\\Users\\SANDEEP\\anaconda3\\envs\\tesnorflow\\lib\\importlib\\__init__.py\", line 126, in import_module\n",
      "    return _bootstrap._gcd_import(name[level:], package, level)\n",
      "  File \"<frozen importlib._bootstrap>\", line 994, in _gcd_import\n",
      "  File \"<frozen importlib._bootstrap>\", line 971, in _find_and_load\n",
      "  File \"<frozen importlib._bootstrap>\", line 953, in _find_and_load_unlocked\n",
      "ModuleNotFoundError: No module named 'tensorflow_core.estimator'\n"
     ]
    }
   ],
   "source": [
    "from skimage import io"
   ]
  },
  {
   "cell_type": "code",
   "execution_count": 8,
   "metadata": {},
   "outputs": [
    {
     "name": "stdout",
     "output_type": "stream",
     "text": [
      "ERROR! Session/line number was not unique in database. History logging moved to new session 26\n"
     ]
    }
   ],
   "source": [
    "import io"
   ]
  },
  {
   "cell_type": "code",
   "execution_count": 9,
   "metadata": {
    "collapsed": true
   },
   "outputs": [],
   "source": [
    "import io"
   ]
  },
  {
   "cell_type": "code",
   "execution_count": 10,
   "metadata": {
    "collapsed": true
   },
   "outputs": [],
   "source": [
    "import os"
   ]
  },
  {
   "cell_type": "code",
   "execution_count": 26,
   "metadata": {
    "collapsed": true
   },
   "outputs": [],
   "source": [
    "file=\"C:/Users/SANDEEP/Desktop/mul/\""
   ]
  },
  {
   "cell_type": "code",
   "execution_count": 27,
   "metadata": {},
   "outputs": [
    {
     "data": {
      "text/plain": [
       "'C:/Users/SANDEEP/Desktop/mul/'"
      ]
     },
     "execution_count": 27,
     "metadata": {},
     "output_type": "execute_result"
    }
   ],
   "source": [
    "file"
   ]
  },
  {
   "cell_type": "code",
   "execution_count": 28,
   "metadata": {
    "collapsed": true
   },
   "outputs": [],
   "source": [
    "iam_list=os.listdir(file)"
   ]
  },
  {
   "cell_type": "code",
   "execution_count": 29,
   "metadata": {},
   "outputs": [
    {
     "name": "stdout",
     "output_type": "stream",
     "text": [
      "dhoni.jpg\n",
      "Virat.jpg\n"
     ]
    }
   ],
   "source": [
    "for i in iam_list:\n",
    "    print(i)"
   ]
  },
  {
   "cell_type": "code",
   "execution_count": 30,
   "metadata": {},
   "outputs": [
    {
     "name": "stdout",
     "output_type": "stream",
     "text": [
      "dhoni.jpg\n",
      "Virat.jpg\n"
     ]
    }
   ],
   "source": [
    "for i in iam_list:\n",
    "    print(i)"
   ]
  },
  {
   "cell_type": "code",
   "execution_count": 16,
   "metadata": {},
   "outputs": [
    {
     "name": "stdout",
     "output_type": "stream",
     "text": [
      "(0, 'dhoni.jpg')\n",
      "(1, 'Virat.jpg')\n"
     ]
    }
   ],
   "source": [
    "for i in enumerate(iam_list):\n",
    "    print(i)"
   ]
  },
  {
   "cell_type": "code",
   "execution_count": 17,
   "metadata": {},
   "outputs": [
    {
     "name": "stdout",
     "output_type": "stream",
     "text": [
      "dhoni.jpg\n",
      "Virat.jpg\n"
     ]
    }
   ],
   "source": [
    "for ind,ima_name in enumerate(iam_list):\n",
    "    print(ima_name)"
   ]
  },
  {
   "cell_type": "code",
   "execution_count": 31,
   "metadata": {},
   "outputs": [
    {
     "name": "stdout",
     "output_type": "stream",
     "text": [
      "dhoni.jpg\n",
      "Virat.jpg\n"
     ]
    }
   ],
   "source": [
    "for ind,ima_name in enumerate(iam_list):\n",
    "    if ima_name.split(\".\")[1]==\"jpg\":\n",
    "        print(ima_name)\n",
    "    "
   ]
  },
  {
   "cell_type": "code",
   "execution_count": 19,
   "metadata": {
    "collapsed": true
   },
   "outputs": [],
   "source": [
    "import numpy as np"
   ]
  },
  {
   "cell_type": "code",
   "execution_count": 20,
   "metadata": {
    "collapsed": true
   },
   "outputs": [],
   "source": [
    "import pandas as pd"
   ]
  },
  {
   "cell_type": "code",
   "execution_count": 21,
   "metadata": {
    "collapsed": true
   },
   "outputs": [],
   "source": [
    "from PIL import Image"
   ]
  },
  {
   "cell_type": "code",
   "execution_count": 22,
   "metadata": {
    "collapsed": true
   },
   "outputs": [],
   "source": [
    "dataset=[]"
   ]
  },
  {
   "cell_type": "code",
   "execution_count": null,
   "metadata": {},
   "outputs": [
    {
     "name": "stderr",
     "output_type": "stream",
     "text": [
      "ERROR:root:Internal Python error in the inspect module.\n",
      "Below is the traceback from this internal error.\n",
      "\n",
      "ERROR:root:Internal Python error in the inspect module.\n",
      "Below is the traceback from this internal error.\n",
      "\n",
      "ERROR:root:Internal Python error in the inspect module.\n",
      "Below is the traceback from this internal error.\n",
      "\n"
     ]
    },
    {
     "name": "stdout",
     "output_type": "stream",
     "text": [
      "Traceback (most recent call last):\n",
      "  File \"C:\\Users\\SANDEEP\\anaconda3\\envs\\tesnorflow\\lib\\site-packages\\IPython\\core\\interactiveshell.py\", line 3343, in run_code\n",
      "    exec(code_obj, self.user_global_ns, self.user_ns)\n",
      "  File \"<ipython-input-41-a5dd8509beb8>\", line 3, in <module>\n",
      "    img=io.imread(file+ima_name)\n",
      "AttributeError: module 'io' has no attribute 'imread'\n",
      "\n",
      "During handling of the above exception, another exception occurred:\n",
      "\n",
      "Traceback (most recent call last):\n",
      "  File \"C:\\Users\\SANDEEP\\anaconda3\\envs\\tesnorflow\\lib\\site-packages\\IPython\\core\\interactiveshell.py\", line 2044, in showtraceback\n",
      "    stb = value._render_traceback_()\n",
      "AttributeError: 'AttributeError' object has no attribute '_render_traceback_'\n",
      "\n",
      "During handling of the above exception, another exception occurred:\n",
      "\n",
      "Traceback (most recent call last):\n",
      "  File \"C:\\Users\\SANDEEP\\anaconda3\\envs\\tesnorflow\\lib\\site-packages\\IPython\\core\\ultratb.py\", line 1169, in get_records\n",
      "    return _fixed_getinnerframes(etb, number_of_lines_of_context, tb_offset)\n",
      "  File \"C:\\Users\\SANDEEP\\anaconda3\\envs\\tesnorflow\\lib\\site-packages\\IPython\\core\\ultratb.py\", line 316, in wrapped\n",
      "    return f(*args, **kwargs)\n",
      "  File \"C:\\Users\\SANDEEP\\anaconda3\\envs\\tesnorflow\\lib\\site-packages\\IPython\\core\\ultratb.py\", line 350, in _fixed_getinnerframes\n",
      "    records = fix_frame_records_filenames(inspect.getinnerframes(etb, context))\n",
      "  File \"C:\\Users\\SANDEEP\\anaconda3\\envs\\tesnorflow\\lib\\inspect.py\", line 1490, in getinnerframes\n",
      "    frameinfo = (tb.tb_frame,) + getframeinfo(tb, context)\n",
      "  File \"C:\\Users\\SANDEEP\\anaconda3\\envs\\tesnorflow\\lib\\inspect.py\", line 1448, in getframeinfo\n",
      "    filename = getsourcefile(frame) or getfile(frame)\n",
      "  File \"C:\\Users\\SANDEEP\\anaconda3\\envs\\tesnorflow\\lib\\inspect.py\", line 696, in getsourcefile\n",
      "    if getattr(getmodule(object, filename), '__loader__', None) is not None:\n",
      "  File \"C:\\Users\\SANDEEP\\anaconda3\\envs\\tesnorflow\\lib\\inspect.py\", line 733, in getmodule\n",
      "    if ismodule(module) and hasattr(module, '__file__'):\n",
      "  File \"C:\\Users\\SANDEEP\\anaconda3\\envs\\tesnorflow\\lib\\site-packages\\tensorflow\\__init__.py\", line 50, in __getattr__\n",
      "    module = self._load()\n",
      "  File \"C:\\Users\\SANDEEP\\anaconda3\\envs\\tesnorflow\\lib\\site-packages\\tensorflow\\__init__.py\", line 44, in _load\n",
      "    module = _importlib.import_module(self.__name__)\n",
      "  File \"C:\\Users\\SANDEEP\\anaconda3\\envs\\tesnorflow\\lib\\importlib\\__init__.py\", line 126, in import_module\n",
      "    return _bootstrap._gcd_import(name[level:], package, level)\n",
      "  File \"<frozen importlib._bootstrap>\", line 994, in _gcd_import\n",
      "  File \"<frozen importlib._bootstrap>\", line 971, in _find_and_load\n",
      "  File \"<frozen importlib._bootstrap>\", line 953, in _find_and_load_unlocked\n",
      "ModuleNotFoundError: No module named 'tensorflow_core.estimator'\n",
      "Traceback (most recent call last):\n",
      "  File \"C:\\Users\\SANDEEP\\anaconda3\\envs\\tesnorflow\\lib\\site-packages\\IPython\\core\\interactiveshell.py\", line 3343, in run_code\n",
      "    exec(code_obj, self.user_global_ns, self.user_ns)\n",
      "  File \"<ipython-input-41-a5dd8509beb8>\", line 3, in <module>\n",
      "    img=io.imread(file+ima_name)\n",
      "AttributeError: module 'io' has no attribute 'imread'\n",
      "\n",
      "During handling of the above exception, another exception occurred:\n",
      "\n",
      "Traceback (most recent call last):\n",
      "  File \"C:\\Users\\SANDEEP\\anaconda3\\envs\\tesnorflow\\lib\\site-packages\\IPython\\core\\interactiveshell.py\", line 2044, in showtraceback\n",
      "    stb = value._render_traceback_()\n",
      "AttributeError: 'AttributeError' object has no attribute '_render_traceback_'\n",
      "\n",
      "During handling of the above exception, another exception occurred:\n",
      "\n",
      "Traceback (most recent call last):\n",
      "  File \"C:\\Users\\SANDEEP\\anaconda3\\envs\\tesnorflow\\lib\\site-packages\\IPython\\core\\interactiveshell.py\", line 3263, in run_ast_nodes\n",
      "    if (await self.run_code(code, result,  async_=asy)):\n",
      "  File \"C:\\Users\\SANDEEP\\anaconda3\\envs\\tesnorflow\\lib\\site-packages\\IPython\\core\\interactiveshell.py\", line 3360, in run_code\n",
      "    self.showtraceback(running_compiled_code=True)\n",
      "  File \"C:\\Users\\SANDEEP\\anaconda3\\envs\\tesnorflow\\lib\\site-packages\\IPython\\core\\interactiveshell.py\", line 2047, in showtraceback\n",
      "    value, tb, tb_offset=tb_offset)\n",
      "  File \"C:\\Users\\SANDEEP\\anaconda3\\envs\\tesnorflow\\lib\\site-packages\\IPython\\core\\ultratb.py\", line 1436, in structured_traceback\n",
      "    self, etype, value, tb, tb_offset, number_of_lines_of_context)\n",
      "  File \"C:\\Users\\SANDEEP\\anaconda3\\envs\\tesnorflow\\lib\\site-packages\\IPython\\core\\ultratb.py\", line 1336, in structured_traceback\n",
      "    self, etype, value, tb, tb_offset, number_of_lines_of_context\n",
      "  File \"C:\\Users\\SANDEEP\\anaconda3\\envs\\tesnorflow\\lib\\site-packages\\IPython\\core\\ultratb.py\", line 1193, in structured_traceback\n",
      "    tb_offset)\n",
      "  File \"C:\\Users\\SANDEEP\\anaconda3\\envs\\tesnorflow\\lib\\site-packages\\IPython\\core\\ultratb.py\", line 1150, in format_exception_as_a_whole\n",
      "    last_unique, recursion_repeat = find_recursion(orig_etype, evalue, records)\n",
      "  File \"C:\\Users\\SANDEEP\\anaconda3\\envs\\tesnorflow\\lib\\site-packages\\IPython\\core\\ultratb.py\", line 451, in find_recursion\n",
      "    return len(records), 0\n",
      "TypeError: object of type 'NoneType' has no len()\n",
      "\n",
      "During handling of the above exception, another exception occurred:\n",
      "\n",
      "Traceback (most recent call last):\n",
      "  File \"C:\\Users\\SANDEEP\\anaconda3\\envs\\tesnorflow\\lib\\site-packages\\IPython\\core\\interactiveshell.py\", line 2044, in showtraceback\n",
      "    stb = value._render_traceback_()\n",
      "AttributeError: 'TypeError' object has no attribute '_render_traceback_'\n",
      "\n",
      "During handling of the above exception, another exception occurred:\n",
      "\n",
      "Traceback (most recent call last):\n",
      "  File \"C:\\Users\\SANDEEP\\anaconda3\\envs\\tesnorflow\\lib\\site-packages\\IPython\\core\\ultratb.py\", line 1169, in get_records\n",
      "    return _fixed_getinnerframes(etb, number_of_lines_of_context, tb_offset)\n",
      "  File \"C:\\Users\\SANDEEP\\anaconda3\\envs\\tesnorflow\\lib\\site-packages\\IPython\\core\\ultratb.py\", line 316, in wrapped\n",
      "    return f(*args, **kwargs)\n",
      "  File \"C:\\Users\\SANDEEP\\anaconda3\\envs\\tesnorflow\\lib\\site-packages\\IPython\\core\\ultratb.py\", line 350, in _fixed_getinnerframes\n",
      "    records = fix_frame_records_filenames(inspect.getinnerframes(etb, context))\n",
      "  File \"C:\\Users\\SANDEEP\\anaconda3\\envs\\tesnorflow\\lib\\inspect.py\", line 1490, in getinnerframes\n",
      "    frameinfo = (tb.tb_frame,) + getframeinfo(tb, context)\n",
      "  File \"C:\\Users\\SANDEEP\\anaconda3\\envs\\tesnorflow\\lib\\inspect.py\", line 1448, in getframeinfo\n",
      "    filename = getsourcefile(frame) or getfile(frame)\n",
      "  File \"C:\\Users\\SANDEEP\\anaconda3\\envs\\tesnorflow\\lib\\inspect.py\", line 696, in getsourcefile\n",
      "    if getattr(getmodule(object, filename), '__loader__', None) is not None:\n",
      "  File \"C:\\Users\\SANDEEP\\anaconda3\\envs\\tesnorflow\\lib\\inspect.py\", line 733, in getmodule\n",
      "    if ismodule(module) and hasattr(module, '__file__'):\n",
      "  File \"C:\\Users\\SANDEEP\\anaconda3\\envs\\tesnorflow\\lib\\site-packages\\tensorflow\\__init__.py\", line 50, in __getattr__\n",
      "    module = self._load()\n",
      "  File \"C:\\Users\\SANDEEP\\anaconda3\\envs\\tesnorflow\\lib\\site-packages\\tensorflow\\__init__.py\", line 44, in _load\n",
      "    module = _importlib.import_module(self.__name__)\n",
      "  File \"C:\\Users\\SANDEEP\\anaconda3\\envs\\tesnorflow\\lib\\importlib\\__init__.py\", line 126, in import_module\n",
      "    return _bootstrap._gcd_import(name[level:], package, level)\n",
      "  File \"<frozen importlib._bootstrap>\", line 994, in _gcd_import\n",
      "  File \"<frozen importlib._bootstrap>\", line 971, in _find_and_load\n",
      "  File \"<frozen importlib._bootstrap>\", line 953, in _find_and_load_unlocked\n",
      "ModuleNotFoundError: No module named 'tensorflow_core.estimator'\n",
      "Traceback (most recent call last):\n",
      "  File \"C:\\Users\\SANDEEP\\anaconda3\\envs\\tesnorflow\\lib\\site-packages\\IPython\\core\\interactiveshell.py\", line 3343, in run_code\n",
      "    exec(code_obj, self.user_global_ns, self.user_ns)\n",
      "  File \"<ipython-input-41-a5dd8509beb8>\", line 3, in <module>\n",
      "    img=io.imread(file+ima_name)\n",
      "AttributeError: module 'io' has no attribute 'imread'\n",
      "\n",
      "During handling of the above exception, another exception occurred:\n",
      "\n",
      "Traceback (most recent call last):\n",
      "  File \"C:\\Users\\SANDEEP\\anaconda3\\envs\\tesnorflow\\lib\\site-packages\\IPython\\core\\interactiveshell.py\", line 2044, in showtraceback\n",
      "    stb = value._render_traceback_()\n",
      "AttributeError: 'AttributeError' object has no attribute '_render_traceback_'\n",
      "\n",
      "During handling of the above exception, another exception occurred:\n",
      "\n",
      "Traceback (most recent call last):\n",
      "  File \"C:\\Users\\SANDEEP\\anaconda3\\envs\\tesnorflow\\lib\\site-packages\\IPython\\core\\interactiveshell.py\", line 3263, in run_ast_nodes\n",
      "    if (await self.run_code(code, result,  async_=asy)):\n",
      "  File \"C:\\Users\\SANDEEP\\anaconda3\\envs\\tesnorflow\\lib\\site-packages\\IPython\\core\\interactiveshell.py\", line 3360, in run_code\n",
      "    self.showtraceback(running_compiled_code=True)\n",
      "  File \"C:\\Users\\SANDEEP\\anaconda3\\envs\\tesnorflow\\lib\\site-packages\\IPython\\core\\interactiveshell.py\", line 2047, in showtraceback\n",
      "    value, tb, tb_offset=tb_offset)\n",
      "  File \"C:\\Users\\SANDEEP\\anaconda3\\envs\\tesnorflow\\lib\\site-packages\\IPython\\core\\ultratb.py\", line 1436, in structured_traceback\n",
      "    self, etype, value, tb, tb_offset, number_of_lines_of_context)\n",
      "  File \"C:\\Users\\SANDEEP\\anaconda3\\envs\\tesnorflow\\lib\\site-packages\\IPython\\core\\ultratb.py\", line 1336, in structured_traceback\n",
      "    self, etype, value, tb, tb_offset, number_of_lines_of_context\n",
      "  File \"C:\\Users\\SANDEEP\\anaconda3\\envs\\tesnorflow\\lib\\site-packages\\IPython\\core\\ultratb.py\", line 1193, in structured_traceback\n",
      "    tb_offset)\n",
      "  File \"C:\\Users\\SANDEEP\\anaconda3\\envs\\tesnorflow\\lib\\site-packages\\IPython\\core\\ultratb.py\", line 1150, in format_exception_as_a_whole\n",
      "    last_unique, recursion_repeat = find_recursion(orig_etype, evalue, records)\n",
      "  File \"C:\\Users\\SANDEEP\\anaconda3\\envs\\tesnorflow\\lib\\site-packages\\IPython\\core\\ultratb.py\", line 451, in find_recursion\n",
      "    return len(records), 0\n",
      "TypeError: object of type 'NoneType' has no len()\n",
      "\n",
      "During handling of the above exception, another exception occurred:\n",
      "\n",
      "Traceback (most recent call last):\n",
      "  File \"C:\\Users\\SANDEEP\\anaconda3\\envs\\tesnorflow\\lib\\site-packages\\IPython\\core\\interactiveshell.py\", line 2044, in showtraceback\n",
      "    stb = value._render_traceback_()\n",
      "AttributeError: 'TypeError' object has no attribute '_render_traceback_'\n",
      "\n",
      "During handling of the above exception, another exception occurred:\n",
      "\n",
      "Traceback (most recent call last):\n",
      "  File \"C:\\Users\\SANDEEP\\anaconda3\\envs\\tesnorflow\\lib\\site-packages\\IPython\\core\\interactiveshell.py\", line 2895, in _run_cell\n",
      "    return runner(coro)\n",
      "  File \"C:\\Users\\SANDEEP\\anaconda3\\envs\\tesnorflow\\lib\\site-packages\\IPython\\core\\async_helpers.py\", line 68, in _pseudo_sync_runner\n",
      "    coro.send(None)\n",
      "  File \"C:\\Users\\SANDEEP\\anaconda3\\envs\\tesnorflow\\lib\\site-packages\\IPython\\core\\interactiveshell.py\", line 3072, in run_cell_async\n",
      "    interactivity=interactivity, compiler=compiler, result=result)\n",
      "  File \"C:\\Users\\SANDEEP\\anaconda3\\envs\\tesnorflow\\lib\\site-packages\\IPython\\core\\interactiveshell.py\", line 3282, in run_ast_nodes\n",
      "    self.showtraceback()\n",
      "  File \"C:\\Users\\SANDEEP\\anaconda3\\envs\\tesnorflow\\lib\\site-packages\\IPython\\core\\interactiveshell.py\", line 2047, in showtraceback\n",
      "    value, tb, tb_offset=tb_offset)\n",
      "  File \"C:\\Users\\SANDEEP\\anaconda3\\envs\\tesnorflow\\lib\\site-packages\\IPython\\core\\ultratb.py\", line 1436, in structured_traceback\n",
      "    self, etype, value, tb, tb_offset, number_of_lines_of_context)\n",
      "  File \"C:\\Users\\SANDEEP\\anaconda3\\envs\\tesnorflow\\lib\\site-packages\\IPython\\core\\ultratb.py\", line 1336, in structured_traceback\n",
      "    self, etype, value, tb, tb_offset, number_of_lines_of_context\n",
      "  File \"C:\\Users\\SANDEEP\\anaconda3\\envs\\tesnorflow\\lib\\site-packages\\IPython\\core\\ultratb.py\", line 1211, in structured_traceback\n",
      "    chained_exceptions_tb_offset)\n",
      "  File \"C:\\Users\\SANDEEP\\anaconda3\\envs\\tesnorflow\\lib\\site-packages\\IPython\\core\\ultratb.py\", line 1150, in format_exception_as_a_whole\n",
      "    last_unique, recursion_repeat = find_recursion(orig_etype, evalue, records)\n",
      "  File \"C:\\Users\\SANDEEP\\anaconda3\\envs\\tesnorflow\\lib\\site-packages\\IPython\\core\\ultratb.py\", line 451, in find_recursion\n",
      "    return len(records), 0\n",
      "TypeError: object of type 'NoneType' has no len()\n",
      "\n",
      "During handling of the above exception, another exception occurred:\n",
      "\n",
      "Traceback (most recent call last):\n",
      "  File \"C:\\Users\\SANDEEP\\anaconda3\\envs\\tesnorflow\\lib\\site-packages\\IPython\\core\\interactiveshell.py\", line 2044, in showtraceback\n",
      "    stb = value._render_traceback_()\n",
      "AttributeError: 'TypeError' object has no attribute '_render_traceback_'\n",
      "\n",
      "During handling of the above exception, another exception occurred:\n",
      "\n",
      "Traceback (most recent call last):\n",
      "  File \"C:\\Users\\SANDEEP\\anaconda3\\envs\\tesnorflow\\lib\\site-packages\\IPython\\core\\ultratb.py\", line 1169, in get_records\n",
      "    return _fixed_getinnerframes(etb, number_of_lines_of_context, tb_offset)\n",
      "  File \"C:\\Users\\SANDEEP\\anaconda3\\envs\\tesnorflow\\lib\\site-packages\\IPython\\core\\ultratb.py\", line 316, in wrapped\n",
      "    return f(*args, **kwargs)\n",
      "  File \"C:\\Users\\SANDEEP\\anaconda3\\envs\\tesnorflow\\lib\\site-packages\\IPython\\core\\ultratb.py\", line 350, in _fixed_getinnerframes\n",
      "    records = fix_frame_records_filenames(inspect.getinnerframes(etb, context))\n",
      "  File \"C:\\Users\\SANDEEP\\anaconda3\\envs\\tesnorflow\\lib\\inspect.py\", line 1490, in getinnerframes\n",
      "    frameinfo = (tb.tb_frame,) + getframeinfo(tb, context)\n",
      "  File \"C:\\Users\\SANDEEP\\anaconda3\\envs\\tesnorflow\\lib\\inspect.py\", line 1448, in getframeinfo\n",
      "    filename = getsourcefile(frame) or getfile(frame)\n",
      "  File \"C:\\Users\\SANDEEP\\anaconda3\\envs\\tesnorflow\\lib\\inspect.py\", line 696, in getsourcefile\n",
      "    if getattr(getmodule(object, filename), '__loader__', None) is not None:\n",
      "  File \"C:\\Users\\SANDEEP\\anaconda3\\envs\\tesnorflow\\lib\\inspect.py\", line 733, in getmodule\n",
      "    if ismodule(module) and hasattr(module, '__file__'):\n",
      "  File \"C:\\Users\\SANDEEP\\anaconda3\\envs\\tesnorflow\\lib\\site-packages\\tensorflow\\__init__.py\", line 50, in __getattr__\n",
      "    module = self._load()\n",
      "  File \"C:\\Users\\SANDEEP\\anaconda3\\envs\\tesnorflow\\lib\\site-packages\\tensorflow\\__init__.py\", line 44, in _load\n",
      "    module = _importlib.import_module(self.__name__)\n",
      "  File \"C:\\Users\\SANDEEP\\anaconda3\\envs\\tesnorflow\\lib\\importlib\\__init__.py\", line 126, in import_module\n",
      "    return _bootstrap._gcd_import(name[level:], package, level)\n",
      "  File \"<frozen importlib._bootstrap>\", line 994, in _gcd_import\n",
      "  File \"<frozen importlib._bootstrap>\", line 971, in _find_and_load\n",
      "  File \"<frozen importlib._bootstrap>\", line 953, in _find_and_load_unlocked\n",
      "ModuleNotFoundError: No module named 'tensorflow_core.estimator'\n"
     ]
    }
   ],
   "source": [
    "for ind, ima_name in enumerate(iam_list):\n",
    "    if ima_name.split(\".\")[1]==\"jpg\":\n",
    "        img=io.imread(file+ima_name)\n",
    "        print(img)"
   ]
  },
  {
   "cell_type": "code",
   "execution_count": 23,
   "metadata": {},
   "outputs": [
    {
     "name": "stdout",
     "output_type": "stream",
     "text": [
      "ERROR! Session/line number was not unique in database. History logging moved to new session 28\n"
     ]
    }
   ],
   "source": [
    "import cv2"
   ]
  },
  {
   "cell_type": "code",
   "execution_count": 24,
   "metadata": {
    "collapsed": true
   },
   "outputs": [],
   "source": [
    "import cv2"
   ]
  },
  {
   "cell_type": "code",
   "execution_count": 34,
   "metadata": {
    "collapsed": true
   },
   "outputs": [],
   "source": [
    "for ind, ima_name in enumerate(iam_list):\n",
    "    if ima_name.split(\".\")[1]==\"jpg\":\n",
    "        img=cv2.imread(file+ima_name)\n",
    "        img=cv2.resize(img,(128,128))\n",
    "        dataset.append(np.array(img))"
   ]
  },
  {
   "cell_type": "code",
   "execution_count": 35,
   "metadata": {},
   "outputs": [
    {
     "data": {
      "text/plain": [
       "[array([[[182, 151, 147],\n",
       "         [171, 140, 137],\n",
       "         [161, 130, 126],\n",
       "         ...,\n",
       "         [124, 106, 105],\n",
       "         [131, 113, 112],\n",
       "         [145, 120, 110]],\n",
       " \n",
       "        [[170, 141, 137],\n",
       "         [161, 132, 128],\n",
       "         [151, 122, 117],\n",
       "         ...,\n",
       "         [130, 115, 113],\n",
       "         [134, 118, 117],\n",
       "         [142, 120, 116]],\n",
       " \n",
       "        [[154, 127, 124],\n",
       "         [144, 118, 114],\n",
       "         [137, 110, 105],\n",
       "         ...,\n",
       "         [127, 114, 112],\n",
       "         [132, 119, 117],\n",
       "         [139, 122, 119]],\n",
       " \n",
       "        ...,\n",
       " \n",
       "        [[169, 159, 206],\n",
       "         [169, 162, 200],\n",
       "         [169, 166, 193],\n",
       "         ...,\n",
       "         [163, 113, 199],\n",
       "         [168, 123, 195],\n",
       "         [171, 131, 189]],\n",
       " \n",
       "        [[178, 168, 215],\n",
       "         [174, 167, 204],\n",
       "         [175, 171, 198],\n",
       "         ...,\n",
       "         [148, 111, 221],\n",
       "         [155, 122, 217],\n",
       "         [166, 133, 212]],\n",
       " \n",
       "        [[184, 175, 222],\n",
       "         [181, 174, 211],\n",
       "         [179, 175, 202],\n",
       "         ...,\n",
       "         [142, 117, 237],\n",
       "         [146, 127, 231],\n",
       "         [158, 132, 226]]], dtype=uint8),\n",
       " array([[[ 31,  39,  45],\n",
       "         [ 29,  36,  40],\n",
       "         [ 28,  35,  38],\n",
       "         ...,\n",
       "         [ 62,  98, 127],\n",
       "         [ 53,  90, 118],\n",
       "         [ 52,  86, 115]],\n",
       " \n",
       "        [[ 29,  38,  44],\n",
       "         [ 28,  34,  39],\n",
       "         [ 27,  34,  37],\n",
       "         ...,\n",
       "         [ 52,  85, 111],\n",
       "         [ 42,  75, 101],\n",
       "         [ 40,  70,  97]],\n",
       " \n",
       "        [[ 29,  37,  43],\n",
       "         [ 28,  37,  41],\n",
       "         [ 28,  35,  38],\n",
       "         ...,\n",
       "         [ 35,  65,  91],\n",
       "         [ 27,  57,  82],\n",
       "         [ 34,  60,  85]],\n",
       " \n",
       "        ...,\n",
       " \n",
       "        [[ 30,  29,  25],\n",
       "         [ 25,  24,  21],\n",
       "         [ 24,  24,  19],\n",
       "         ...,\n",
       "         [ 99, 126, 172],\n",
       "         [ 83, 105, 150],\n",
       "         [ 79,  99, 143]],\n",
       " \n",
       "        [[ 23,  24,  22],\n",
       "         [ 22,  23,  21],\n",
       "         [ 20,  21,  17],\n",
       "         ...,\n",
       "         [ 74, 103, 151],\n",
       "         [ 85, 109, 160],\n",
       "         [ 59,  80, 134]],\n",
       " \n",
       "        [[ 24,  25,  24],\n",
       "         [ 20,  21,  19],\n",
       "         [ 21,  22,  19],\n",
       "         ...,\n",
       "         [ 88, 108, 139],\n",
       "         [ 78,  97, 123],\n",
       "         [ 69,  87, 111]]], dtype=uint8)]"
      ]
     },
     "execution_count": 35,
     "metadata": {},
     "output_type": "execute_result"
    }
   ],
   "source": [
    "dataset"
   ]
  },
  {
   "cell_type": "code",
   "execution_count": 36,
   "metadata": {
    "collapsed": true
   },
   "outputs": [],
   "source": [
    "ar_data=np.array(dataset)"
   ]
  },
  {
   "cell_type": "code",
   "execution_count": 37,
   "metadata": {},
   "outputs": [
    {
     "data": {
      "text/plain": [
       "array([[[[182, 151, 147],\n",
       "         [171, 140, 137],\n",
       "         [161, 130, 126],\n",
       "         ...,\n",
       "         [124, 106, 105],\n",
       "         [131, 113, 112],\n",
       "         [145, 120, 110]],\n",
       "\n",
       "        [[170, 141, 137],\n",
       "         [161, 132, 128],\n",
       "         [151, 122, 117],\n",
       "         ...,\n",
       "         [130, 115, 113],\n",
       "         [134, 118, 117],\n",
       "         [142, 120, 116]],\n",
       "\n",
       "        [[154, 127, 124],\n",
       "         [144, 118, 114],\n",
       "         [137, 110, 105],\n",
       "         ...,\n",
       "         [127, 114, 112],\n",
       "         [132, 119, 117],\n",
       "         [139, 122, 119]],\n",
       "\n",
       "        ...,\n",
       "\n",
       "        [[169, 159, 206],\n",
       "         [169, 162, 200],\n",
       "         [169, 166, 193],\n",
       "         ...,\n",
       "         [163, 113, 199],\n",
       "         [168, 123, 195],\n",
       "         [171, 131, 189]],\n",
       "\n",
       "        [[178, 168, 215],\n",
       "         [174, 167, 204],\n",
       "         [175, 171, 198],\n",
       "         ...,\n",
       "         [148, 111, 221],\n",
       "         [155, 122, 217],\n",
       "         [166, 133, 212]],\n",
       "\n",
       "        [[184, 175, 222],\n",
       "         [181, 174, 211],\n",
       "         [179, 175, 202],\n",
       "         ...,\n",
       "         [142, 117, 237],\n",
       "         [146, 127, 231],\n",
       "         [158, 132, 226]]],\n",
       "\n",
       "\n",
       "       [[[ 31,  39,  45],\n",
       "         [ 29,  36,  40],\n",
       "         [ 28,  35,  38],\n",
       "         ...,\n",
       "         [ 62,  98, 127],\n",
       "         [ 53,  90, 118],\n",
       "         [ 52,  86, 115]],\n",
       "\n",
       "        [[ 29,  38,  44],\n",
       "         [ 28,  34,  39],\n",
       "         [ 27,  34,  37],\n",
       "         ...,\n",
       "         [ 52,  85, 111],\n",
       "         [ 42,  75, 101],\n",
       "         [ 40,  70,  97]],\n",
       "\n",
       "        [[ 29,  37,  43],\n",
       "         [ 28,  37,  41],\n",
       "         [ 28,  35,  38],\n",
       "         ...,\n",
       "         [ 35,  65,  91],\n",
       "         [ 27,  57,  82],\n",
       "         [ 34,  60,  85]],\n",
       "\n",
       "        ...,\n",
       "\n",
       "        [[ 30,  29,  25],\n",
       "         [ 25,  24,  21],\n",
       "         [ 24,  24,  19],\n",
       "         ...,\n",
       "         [ 99, 126, 172],\n",
       "         [ 83, 105, 150],\n",
       "         [ 79,  99, 143]],\n",
       "\n",
       "        [[ 23,  24,  22],\n",
       "         [ 22,  23,  21],\n",
       "         [ 20,  21,  17],\n",
       "         ...,\n",
       "         [ 74, 103, 151],\n",
       "         [ 85, 109, 160],\n",
       "         [ 59,  80, 134]],\n",
       "\n",
       "        [[ 24,  25,  24],\n",
       "         [ 20,  21,  19],\n",
       "         [ 21,  22,  19],\n",
       "         ...,\n",
       "         [ 88, 108, 139],\n",
       "         [ 78,  97, 123],\n",
       "         [ 69,  87, 111]]]], dtype=uint8)"
      ]
     },
     "execution_count": 37,
     "metadata": {},
     "output_type": "execute_result"
    }
   ],
   "source": [
    "ar_data"
   ]
  },
  {
   "cell_type": "code",
   "execution_count": 38,
   "metadata": {},
   "outputs": [
    {
     "data": {
      "text/plain": [
       "(2, 128, 128, 3)"
      ]
     },
     "execution_count": 38,
     "metadata": {},
     "output_type": "execute_result"
    }
   ],
   "source": [
    "ar_data.shape"
   ]
  },
  {
   "cell_type": "code",
   "execution_count": 39,
   "metadata": {},
   "outputs": [
    {
     "data": {
      "text/plain": [
       "(128, 128, 3)"
      ]
     },
     "execution_count": 39,
     "metadata": {},
     "output_type": "execute_result"
    }
   ],
   "source": [
    "ar_data[1].shape"
   ]
  },
  {
   "cell_type": "code",
   "execution_count": 40,
   "metadata": {
    "collapsed": true
   },
   "outputs": [],
   "source": [
    "c=0\n",
    "for batch in img_gen.flow(ar_data, batch_size=25,save_to_dir=file,save_prefix='001',save_format='png'):\n",
    "    c=c+1\n",
    "    if c>=25:\n",
    "        break"
   ]
  },
  {
   "cell_type": "code",
   "execution_count": null,
   "metadata": {
    "collapsed": true
   },
   "outputs": [],
   "source": []
  }
 ],
 "metadata": {
  "kernelspec": {
   "display_name": "Python 3",
   "language": "python",
   "name": "python3"
  },
  "language_info": {
   "codemirror_mode": {
    "name": "ipython",
    "version": 3
   },
   "file_extension": ".py",
   "mimetype": "text/x-python",
   "name": "python",
   "nbconvert_exporter": "python",
   "pygments_lexer": "ipython3",
   "version": "3.6.4"
  }
 },
 "nbformat": 4,
 "nbformat_minor": 5
}
